No exception occurred
I am inside finally block
Test Completed
